<?xml version="1.0" ?>
<!-- =================================================================================== -->
<!-- |    This document was autogenerated by xacro from robots/hsrb4s.urdf.xacro       | -->
<!-- |    EDITING THIS FILE BY HAND IS NOT RECOMMENDED                                 | -->
<!-- =================================================================================== -->
<robot name="hsrb">
  <material name="body_main">
    <color rgba="1.0 0.0 0.0 1.0"/>
  </material>
  <material name="body_sub">
    <color rgba="0.3333 0.3333 0.3333 1.0"/>
  </material>
  <material name="wheel">
    <color rgba="0.2 0.2 0.2 1.0"/>
  </material>
  <material name="black">
    <color rgba="0.1 0.1 0.1 1.0"/>
  </material>
  <material name="tablet">
    <color rgba="0.1 0.1 0.2 1.0"/>
  </material>
  <!-- The weight of all hand links is set lightly.
         The reason is to make it easy to adjust the hand control gain in gazebo.
         TODO Reset the weight parameter to the correct value -->
  <link name="base_footprint">
        </link>
  <joint name="base_footprint_joint" type="fixed">
    <parent link="base_footprint"/>
    <child link="base_link"/>
  </joint>
  <link name="base_link">
    <inertial>
      <mass value="50.0"/>
      <origin xyz="-0.025978 -0.005498 0.17633"/>
      <inertia ixx="0.3742" ixy="0.000434172172" ixz="0.03088" iyy="0.3436" iyz="0.01775" izz="0.1509"/>
    </inertial>
    <visual>
      <geometry>
        <mesh filename="package://hsr_description/meshes/base_v2/base_light.dae"/>
      </geometry>
    </visual>
    <visual>
      <geometry>
        <mesh filename="package://hsr_description/meshes/base_v2/body_light.dae"/>
      </geometry>
    </visual>
    <visual>
      <geometry>
        <mesh filename="package://hsr_description/meshes/base_v2/torso_base.dae"/>
      </geometry>
    </visual>
    <collision>
      <geometry>
        <mesh filename="package://hsr_description/meshes/base_v2/base.stl"/>
      </geometry>
    </collision>
  </link>
  <joint name="base_roll_joint" type="continuous">
    <origin rpy="0.0 0.0 0.0" xyz="0.0 0.0 0.0"/>
    <axis xyz="0.0 0.0 1.0"/>
    <limit effort="34.46" velocity="2.5"/>
    <parent link="base_link"/>
    <child link="base_roll_link"/>
    <dynamics damping="0.7"/>
  </joint>
  <link name="base_roll_link">
    <inertial>
      <origin xyz="-0.01948200 0.00219100 0.07101300"/>
      <mass value="10.239419"/>
      <inertia ixx="0.07671000" ixy="-0.01005000" ixz="0.00174900" iyy="0.09057000" iyz="0.00154900" izz="0.14500000"/>
    </inertial>
  </link>
  <joint name="base_r_drive_wheel_joint" type="continuous">
    <origin rpy="0.0 0.0 0.0" xyz="-0.11 -0.133 0.04"/>
    <axis xyz="0.0 1.0 0.0"/>
    <limit effort="11.067" velocity="20.8"/>
    <parent link="base_roll_link"/>
    <child link="base_r_drive_wheel_link"/>
    <dynamics damping="1.0"/>
  </joint>
  <link name="base_r_drive_wheel_link">
    <visual>
      <origin rpy="1.5707963267948966 0.0 0.0" xyz="0.0 0.0 0.0"/>
      <geometry>
        <cylinder length="0.03" radius="0.04"/>
      </geometry>
      <material name="wheel"/>
    </visual>
    <collision>
      <origin rpy="1.5707963267948966 0.0 0.0" xyz="0.0 0.0 0.0"/>
      <geometry>
        <cylinder length="0.03" radius="0.04"/>
      </geometry>
    </collision>
    <inertial>
      <mass value="0.2"/>
      <origin xyz="0 0 0"/>
      <inertia ixx="0.015" ixy="0" ixz="0" iyy="0.015" iyz="0" izz="0.015"/>
    </inertial>
  </link>
  <joint name="base_l_drive_wheel_joint" type="continuous">
    <origin rpy="0.0 0.0 0.0" xyz="-0.11 0.133 0.04"/>
    <axis xyz="0.0 1.0 0.0"/>
    <limit effort="11.067" velocity="20.8"/>
    <parent link="base_roll_link"/>
    <child link="base_l_drive_wheel_link"/>
    <dynamics damping="1.0"/>
  </joint>
  <link name="base_l_drive_wheel_link">
    <visual>
      <origin rpy="1.5707963267948966 0.0 0.0" xyz="0.0 0.0 0.0"/>
      <geometry>
        <cylinder length="0.03" radius="0.04"/>
      </geometry>
      <material name="wheel"/>
    </visual>
    <collision>
      <origin rpy="1.5707963267948966 0.0 0.0" xyz="0.0 0.0 0.0"/>
      <geometry>
        <cylinder length="0.03" radius="0.04"/>
      </geometry>
    </collision>
    <inertial>
      <mass value="0.2"/>
      <origin xyz="0 0 0"/>
      <inertia ixx="0.015" ixy="0" ixz="0" iyy="0.015" iyz="0" izz="0.015"/>
    </inertial>
  </link>
  <joint name="base_r_passive_wheel_x_frame_joint" type="continuous">
    <origin rpy="0.0 0.0 0.0" xyz="0.1495                 -0.055                 0.03"/>
    <axis xyz="1.0 0.0 0.0"/>
    <limit effort="1.0" velocity="3.0"/>
    <parent link="base_roll_link"/>
    <child link="base_r_passive_wheel_x_frame"/>
    <dynamics damping="1.0"/>
  </joint>
  <link name="base_r_passive_wheel_x_frame">
    <inertial>
      <mass value="0.2"/>
      <origin xyz="0 0 0"/>
      <inertia ixx="0.015" ixy="0" ixz="0" iyy="0.015" iyz="0" izz="0.015"/>
    </inertial>
  </link>
  <joint name="base_r_passive_wheel_y_frame_joint" type="continuous">
    <axis xyz="0.0 1.0 0.0"/>
    <limit effort="8.85" velocity="10.0"/>
    <parent link="base_r_passive_wheel_x_frame"/>
    <child link="base_r_passive_wheel_y_frame"/>
  </joint>
  <link name="base_r_passive_wheel_y_frame">
    <inertial>
      <mass value="0.2"/>
      <origin xyz="0 0 0"/>
      <inertia ixx="0.015" ixy="0" ixz="0" iyy="0.015" iyz="0" izz="0.015"/>
    </inertial>
  </link>
  <joint name="base_r_passive_wheel_z_joint" type="continuous">
    <axis xyz="0.0 0.0 1.0"/>
    <limit effort="8.85" velocity="10.0"/>
    <parent link="base_r_passive_wheel_y_frame"/>
    <child link="base_r_passive_wheel_z_link"/>
  </joint>
  <link name="base_r_passive_wheel_z_link">
    <visual>
      <geometry>
        <sphere radius="0.03"/>
      </geometry>
      <material name="wheel"/>
    </visual>
    <collision>
      <geometry>
        <sphere radius="0.03"/>
      </geometry>
    </collision>
    <inertial>
      <mass value="0.2"/>
      <origin xyz="0 0 0"/>
      <inertia ixx="0.015" ixy="0" ixz="0" iyy="0.015" iyz="0" izz="0.015"/>
    </inertial>
  </link>
  <joint name="base_l_passive_wheel_x_frame_joint" type="continuous">
    <origin rpy="0.0 0.0 0.0" xyz="0.1495                 0.055                 0.03"/>
    <axis xyz="1.0 0.0 0.0"/>
    <limit effort="1.0" velocity="3.0"/>
    <parent link="base_roll_link"/>
    <child link="base_l_passive_wheel_x_frame"/>
    <dynamics damping="1.0"/>
  </joint>
  <link name="base_l_passive_wheel_x_frame">
    <inertial>
      <mass value="0.2"/>
      <origin xyz="0 0 0"/>
      <inertia ixx="0.015" ixy="0" ixz="0" iyy="0.015" iyz="0" izz="0.015"/>
    </inertial>
  </link>
  <joint name="base_l_passive_wheel_y_frame_joint" type="continuous">
    <axis xyz="0.0 1.0 0.0"/>
    <limit effort="8.85" velocity="10.0"/>
    <parent link="base_l_passive_wheel_x_frame"/>
    <child link="base_l_passive_wheel_y_frame"/>
  </joint>
  <link name="base_l_passive_wheel_y_frame">
    <inertial>
      <mass value="0.2"/>
      <origin xyz="0 0 0"/>
      <inertia ixx="0.015" ixy="0" ixz="0" iyy="0.015" iyz="0" izz="0.015"/>
    </inertial>
  </link>
  <joint name="base_l_passive_wheel_z_joint" type="continuous">
    <axis xyz="0.0 0.0 1.0"/>
    <limit effort="8.85" velocity="10.0"/>
    <parent link="base_l_passive_wheel_y_frame"/>
    <child link="base_l_passive_wheel_z_link"/>
  </joint>
  <link name="base_l_passive_wheel_z_link">
    <visual>
      <geometry>
        <sphere radius="0.03"/>
      </geometry>
      <material name="wheel"/>
    </visual>
    <collision>
      <geometry>
        <sphere radius="0.03"/>
      </geometry>
    </collision>
    <inertial>
      <mass value="0.2"/>
      <origin xyz="0 0 0"/>
      <inertia ixx="0.015" ixy="0" ixz="0" iyy="0.015" iyz="0" izz="0.015"/>
    </inertial>
  </link>
  <joint name="base_range_sensor_joint" type="fixed">
    <origin rpy="0.0 0.0 0.0" xyz="0.1675 0.0 0.1844"/>
    <parent link="base_link"/>
    <child link="base_range_sensor_link"/>
  </joint>
  <link name="base_range_sensor_link">
    <visual>
      <geometry>
        <mesh filename="package://hsr_description/meshes/sensors/laser.dae"/>
      </geometry>
    </visual>
    <collision>
      <geometry>
        <mesh filename="package://hsr_description/meshes/sensors/laser.stl"/>
      </geometry>
    </collision>
    <inertial>
      <origin xyz="0 0 0"/>
      <mass value="0.01"/>
      <inertia ixx="0.001" ixy="0" ixz="0" iyy="0.001" iyz="0" izz="0.001"/>
    </inertial>
  </link>
  <gazebo reference="base_range_sensor_link">
    <sensor name="base_range_sensor" type="ray">
      <pose>0 0 0 0 0 0</pose>
      <update_rate>30.0</update_rate>
      <visualize>true</visualize>
      <ray>
        <scan>
          <horizontal>
            <samples>721</samples>
            <resolution>1</resolution>
            <min_angle>-2.1</min_angle>
            <max_angle>2.1</max_angle>
          </horizontal>
        </scan>
        <range>
          <min>0.05</min>
          <max>60</max>
          <resolution>0.001</resolution>
        </range>
      </ray>
      <plugin filename="libgazebo_ros_ray_sensor.so" name="base_range_sensor">
        <output_type>sensor_msgs/LaserScan</output_type>
        <frame_name>base_range_sensor_link</frame_name>
        <ros>
          <remapping>~/out:=scan</remapping>
        </ros>
      </plugin>
    </sensor>
  </gazebo>
  <joint name="base_imu_frame_joint" type="fixed">
    <origin rpy="0.0 0.0 0.0" xyz="0.0005 0.1296 0.181"/>
    <parent link="base_link"/>
    <child link="base_imu_frame"/>
  </joint>
  <link name="base_imu_frame">
    <inertial>
      <origin xyz="0 0 0"/>
      <mass value="0.01"/>
      <inertia ixx="0.001" ixy="0" ixz="0" iyy="0.001" iyz="0" izz="0.001"/>
    </inertial>
  </link>
  <gazebo reference="base_imu_frame">
    <sensor name="base_imu" type="imu">
      <update_rate>100.0</update_rate>
      <plugin filename="libgazebo_ros_imu_sensor.so" name="base_imu_plugin">
        <frame_name>/base_imu_frame</frame_name>
        <ros>
          <namespace></namespace>
          <remapping>~/out:=base_imu/data</remapping>
        </ros>
      </plugin>
      <imu>
        <noise>
          <type>gaussian</type>
          <rate>
            <mean>0.0</mean>
            <stddev>2e-4</stddev>
            <bias_mean>0.0000075</bias_mean>
            <bias_stddev>0.0000008</bias_stddev>
          </rate>
          <accel>
            <mean>0.0</mean>
            <stddev>1.7e-2</stddev>
            <bias_mean>0.1</bias_mean>
            <bias_stddev>0.001</bias_stddev>
          </accel>
        </noise>
      </imu>
    </sensor>
  </gazebo>
  <joint name="base_f_bumper_joint" type="fixed">
    <origin rpy="0.0 0.0 0.0" xyz="0.0 0.0 0.0"/>
    <parent link="base_link"/>
    <child link="base_f_bumper_link"/>
  </joint>
  <link name="base_f_bumper_link">
    <!--             <inertial>
                <origin xyz="0.0 0.0 0.0" />
                <mass value="0.06"/>
                <inertia
                    ixx="0.001437"  ixy="0.0"  ixz="0.0"
                    iyy="0.001437" iyz="0.0" izz="0.002875" />
            </inertial> -->
    <visual>
      <geometry>
        <mesh filename="package://hsr_description/meshes/base_v2/bumper.dae"/>
      </geometry>
    </visual>
    <collision>
      <geometry>
        <mesh filename="package://hsr_description/meshes/base_v2/bumper.stl"/>
      </geometry>
    </collision>
  </link>
  <joint name="base_b_bumper_joint" type="fixed">
    <origin rpy="0.0 0.0 3.141592653589793" xyz="0.0 0.0013 0.0"/>
    <parent link="base_link"/>
    <child link="base_b_bumper_link"/>
  </joint>
  <link name="base_b_bumper_link">
    <!--             <inertial>
                <origin xyz="0.0 0.0 0.0" />
                <mass value="0.06"/>
                <inertia
                    ixx="0.001437"  ixy="0.0"  ixz="0.0"
                    iyy="0.001437" iyz="0.0" izz="0.002875" />
            </inertial> -->
    <visual>
      <geometry>
        <mesh filename="package://hsr_description/meshes/base_v2/bumper.dae"/>
      </geometry>
    </visual>
    <collision>
      <geometry>
        <mesh filename="package://hsr_description/meshes/base_v2/bumper.stl"/>
      </geometry>
    </collision>
  </link>
  <gazebo reference="base_link">
    <selfCollide>False</selfCollide>
    <gravity>True</gravity>
    <mu1>0.9</mu1>
    <mu2>0.9</mu2>
  </gazebo>
  <gazebo reference="base_roll_link">
    <selfCollide>False</selfCollide>
    <gravity>True</gravity>
    <mu1>0.9</mu1>
    <mu2>0.9</mu2>
  </gazebo>
  <gazebo reference="base_r_drive_wheel_link">
    <selfCollide>false</selfCollide>
    <gravity>true</gravity>
    <turnGravityOff>false</turnGravityOff>
    <kp>1000000.0</kp>
    <kd>10.0</kd>
    <mu1>1.0</mu1>
    <mu2>1.0</mu2>
    <maxVel>1.0</maxVel>
    <minDepth>0.00</minDepth>
    <material value="Gazebo/FlatBlack"/>
  </gazebo>
  <gazebo reference="base_l_drive_wheel_link">
    <selfCollide>false</selfCollide>
    <gravity>true</gravity>
    <turnGravityOff>false</turnGravityOff>
    <kp>1000000.0</kp>
    <kd>10.0</kd>
    <mu1>1.0</mu1>
    <mu2>1.0</mu2>
    <maxVel>1.0</maxVel>
    <minDepth>0.00</minDepth>
    <material value="Gazebo/FlatBlack"/>
  </gazebo>
  <gazebo reference="base_r_passive_wheel_z_link">
    <selfCollide>false</selfCollide>
    <gravity>true</gravity>
    <mu1>0.1</mu1>
    <mu2>0.1</mu2>
    <maxVel>1.0</maxVel>
    <material value="Gazebo/FlatBlack"/>
  </gazebo>
  <gazebo reference="base_l_passive_wheel_z_link">
    <selfCollide>false</selfCollide>
    <gravity>true</gravity>
    <mu1>0.1</mu1>
    <mu2>0.1</mu2>
    <maxVel>1.0</maxVel>
    <material value="Gazebo/FlatBlack"/>
  </gazebo>
  <gazebo reference="base_range_sensor_link">
    <selfCollide>False</selfCollide>
    <gravity>True</gravity>
    <mu1>0.9</mu1>
    <mu2>0.9</mu2>
  </gazebo>
  <gazebo reference="base_imu_frame">
    <selfCollide>False</selfCollide>
    <gravity>True</gravity>
    <mu1>0.9</mu1>
    <mu2>0.9</mu2>
  </gazebo>
  <gazebo reference="base_f_bumper_link">
    <selfCollide>False</selfCollide>
    <gravity>True</gravity>
    <mu1>0.9</mu1>
    <mu2>0.9</mu2>
    <sensor name="base_f_bumper_contact" type="contact">
      <always_on>true</always_on>
      <update_rate>10</update_rate>
      <contact>
        <collision>base_f_bumper_link_collision</collision>
      </contact>
      <plugin filename="libtmc_gazebo_ros_bumper.so" name="base_f_bumper_bumper_controller">
        <ros>
          <namespace></namespace>
          <remapping>bumper_states:=base_f_bumper_sensor</remapping>
        </ros>
      </plugin>
    </sensor>
  </gazebo>
  <gazebo reference="base_b_bumper_link">
    <selfCollide>False</selfCollide>
    <gravity>True</gravity>
    <mu1>0.9</mu1>
    <mu2>0.9</mu2>
    <sensor name="base_b_bumper_contact" type="contact">
      <always_on>true</always_on>
      <update_rate>10</update_rate>
      <contact>
        <collision>base_b_bumper_link_collision</collision>
      </contact>
      <plugin filename="libtmc_gazebo_ros_bumper.so" name="base_b_bumper_bumper_controller">
        <ros>
          <namespace></namespace>
          <remapping>bumper_states:=base_b_bumper_sensor</remapping>
        </ros>
      </plugin>
    </sensor>
  </gazebo>
  <gazebo>
    <plugin filename="libtmc_gazebo_ros_p3d.so" name="odom_ground_truth">
      <body_name>base_footprint</body_name>
      <frame_name>map</frame_name>
      <update_rate>30</update_rate>
      <xyz_offset>0.0\ 0.0\ 0.0</xyz_offset>
      <rpy_offset>0.0\ 0.0\ 0.0</rpy_offset>
      <ros>
        <namespace></namespace>
        <remapping>odom:=odom_ground_truth</remapping>
      </ros>
    </plugin>
  </gazebo>
  <joint name="torso_lift_joint" type="prismatic">
    <origin rpy="0.0 0.0 0.0" xyz="0.0 0.0 0.752"/>
    <!-- <origin xyz="0.0 0.0 0.752" rpy="0.0 0.0 0.0" /> -->
    <axis xyz="0.0 0.0 1.0"/>
    <!--            <limit effort="300.0" velocity="0.1" lower="0.0" upper="0.345" />-->
    <limit effort="100.0" lower="0.0025" upper="0.335" velocity="0.075"/>
    <parent link="base_link"/>
    <child link="torso_lift_link"/>
    <mimic joint="arm_lift_joint" multiplier="0.5"/>
    <dynamics damping="500.0"/>
  </joint>
  <link name="torso_lift_link">
    <inertial>
      <mass value="3.420779"/>
      <origin xyz="-0.051142 0.003454 -0.2905"/>
      <inertia ixx="0.1045" ixy="-0.000460884801" ixz="0.000101130383" iyy="0.105" iyz="0.002941" izz="0.01284"/>
    </inertial>
    <visual>
      <geometry>
        <mesh filename="package://hsr_description/meshes/torso_v0/torso_light.dae"/>
      </geometry>
    </visual>
    <collision>
      <geometry>
        <mesh filename="package://hsr_description/meshes/torso_v0/torso.stl"/>
      </geometry>
    </collision>
  </link>
  <gazebo reference="torso_lift_link">
    <selfCollide>False</selfCollide>
    <gravity>True</gravity>
    <mu1>0.9</mu1>
    <mu2>0.9</mu2>
  </gazebo>
  <gazebo reference="torso_lift_joint">
    </gazebo>
  <gazebo>
    <plugin filename="libtmc_gazebo_ros_mimic_joint.so" name="torso_mimic_plugin">
      <joint>torso_lift_joint</joint>
      <mimic_joint>arm_lift_joint</mimic_joint>
      <multiplier>0.5</multiplier>
    </plugin>
  </gazebo>
  <joint name="head_pan_joint" type="revolute">
    <origin rpy="0.0 0.0 0.0" xyz="0.0 0.0 0.0"/>
    <axis xyz="0.0 0.0 1.0"/>
    <limit effort="100.0" lower="-3.83" upper="1.74" velocity="1.0"/>
    <safety_controller k_position="100" k_velocity="200000" soft_lower_limit="-3.83" soft_upper_limit="1.74"/>
    <parent link="torso_lift_link"/>
    <child link="head_pan_link"/>
    <dynamics damping="1.0"/>
  </joint>
  <link name="head_pan_link">
    <inertial>
      <mass value="0.571903"/>
      <origin xyz="0.001724 -0.001969 -0.028886"/>
      <inertia ixx="0.0009711421" ixy="0.00006179487" ixz="-0.000113923121" iyy="0.00065335493" iyz="0.000069036305" izz="0.000765202576"/>
    </inertial>
    <visual>
      <geometry>
        <mesh filename="package://hsr_description/meshes/head_v1/head_pan.dae"/>
      </geometry>
    </visual>
    <collision>
      <geometry>
        <mesh filename="package://hsr_description/meshes/head_v1/head_pan.stl"/>
      </geometry>
    </collision>
  </link>
  <joint name="head_tilt_joint" type="revolute">
    <origin rpy="0.0 0.0 0.0" xyz="0.02 0.0 0.0"/>
    <axis xyz="0.0 -1.0 0.0"/>
    <limit effort="100.0" lower="-1.56" upper="0.47" velocity="1.0"/>
    <safety_controller k_position="100" k_velocity="200000" soft_lower_limit="-1.56" soft_upper_limit="0.47"/>
    <parent link="head_pan_link"/>
    <child link="head_tilt_link"/>
    <dynamics damping="10.0"/>
  </joint>
  <link name="head_tilt_link">
    <inertial>
      <mass value="2.123802"/>
      <origin xyz="-0.055376 -0.002436 0.117733"/>
      <inertia ixx="0.01941" ixy="-0.000138091054" ixz="0.005035" iyy="0.01498" iyz="0.000087492537" izz="0.01167"/>
    </inertial>
    <visual>
      <geometry>
        <mesh filename="package://hsr_description/meshes/head_v1/head_upper.dae"/>
      </geometry>
    </visual>
    <visual>
      <geometry>
        <mesh filename="package://hsr_description/meshes/head_v1/head_tilt.dae"/>
      </geometry>
    </visual>
    <visual>
      <geometry>
        <mesh filename="package://hsr_description/meshes/head_v1/tablet_base.dae"/>
      </geometry>
    </visual>
    <collision>
      <geometry>
        <mesh filename="package://hsr_description/meshes/head_v1/head.stl"/>
      </geometry>
    </collision>
    <collision>
      <geometry>
        <mesh filename="package://hsr_description/meshes/head_v1/tablet.stl"/>
      </geometry>
    </collision>
  </link>
  <joint name="head_l_stereo_camera_joint" type="fixed">
    <origin rpy="-1.5707963267948966 0.0 -1.5707963267948966" xyz="0.02 0.07 0.061"/>
    <parent link="head_tilt_link"/>
    <child link="head_l_stereo_camera_link"/>
  </joint>
  <link name="head_l_stereo_camera_link">
    <visual>
      <origin rpy="0.0 0.0 0.0" xyz="0 0 0"/>
      <geometry>
        <mesh filename="package://hsr_description/meshes/sensors/head_camera.dae"/>
      </geometry>
    </visual>
    <inertial>
      <origin xyz="0 0 0"/>
      <mass value="0.01"/>
      <inertia ixx="0.001" ixy="0" ixz="0" iyy="0.001" iyz="0" izz="0.001"/>
    </inertial>
  </link>
  <joint name="head_l_stereo_camera_gazebo_frame_joint" type="fixed">
    <origin rpy="1.5707963267948966 -1.5707963267948966 0.0" xyz="0 0 0"/>
    <parent link="head_l_stereo_camera_link"/>
    <child link="head_l_stereo_camera_gazebo_frame"/>
  </joint>
  <link name="head_l_stereo_camera_gazebo_frame">
    <inertial>
      <origin xyz="0 0 0"/>
      <mass value="0.01"/>
      <inertia ixx="0.001" ixy="0" ixz="0" iyy="0.001" iyz="0" izz="0.001"/>
    </inertial>
  </link>
  <gazebo reference="head_l_stereo_camera_gazebo_frame">
    <sensor name="head_l_stereo_camera" type="camera">
      <update_rate>4.0</update_rate>
      <camera name="head_l_stereo_camera">
        <horizontal_fov>1.16762527</horizontal_fov>
        <image>
          <width>1280</width>
          <height>960</height>
          <format>R8G8B8</format>
        </image>
        <clip>
          <near>0.05</near>
          <far>100</far>
        </clip>
        <noise>
          <type>gaussian</type>
          <mean>0.0</mean>
          <stddev>0.007</stddev>
        </noise>
        <distortion>
          <k1>0.0</k1>
          <k2>0.0</k2>
          <k3>0.0</k3>
          <p1>0.0</p1>
          <p2>0.0</p2>
        </distortion>
      </camera>
      <plugin filename="libgazebo_ros_camera.so" name="head_l_stereo_camera_camera_controller">
        <camera_name>head_l_stereo_camera</camera_name>
        <frame_name>head_l_stereo_camera_frame</frame_name>
        <hack_baseline>0.0</hack_baseline>
        <ros>
          <namespace></namespace>
          <remapping>head_l_stereo_camera/image_raw:=head_l_stereo_camera/image_rect_color</remapping>
        </ros>
      </plugin>
    </sensor>
  </gazebo>
  <joint name="head_r_stereo_camera_joint" type="fixed">
    <origin rpy="-1.5707963267948966 0.0 -1.5707963267948966" xyz="0.02 -0.07 0.061"/>
    <parent link="head_tilt_link"/>
    <child link="head_r_stereo_camera_link"/>
  </joint>
  <link name="head_r_stereo_camera_link">
    <visual>
      <origin rpy="0.0 0.0 0.0" xyz="0 0 0"/>
      <geometry>
        <mesh filename="package://hsr_description/meshes/sensors/head_camera.dae"/>
      </geometry>
    </visual>
    <inertial>
      <origin xyz="0 0 0"/>
      <mass value="0.01"/>
      <inertia ixx="0.001" ixy="0" ixz="0" iyy="0.001" iyz="0" izz="0.001"/>
    </inertial>
  </link>
  <joint name="head_r_stereo_camera_gazebo_frame_joint" type="fixed">
    <origin rpy="1.5707963267948966 -1.5707963267948966 0.0" xyz="0 0 0"/>
    <parent link="head_r_stereo_camera_link"/>
    <child link="head_r_stereo_camera_gazebo_frame"/>
  </joint>
  <link name="head_r_stereo_camera_gazebo_frame">
    <inertial>
      <origin xyz="0 0 0"/>
      <mass value="0.01"/>
      <inertia ixx="0.001" ixy="0" ixz="0" iyy="0.001" iyz="0" izz="0.001"/>
    </inertial>
  </link>
  <gazebo reference="head_r_stereo_camera_gazebo_frame">
    <sensor name="head_r_stereo_camera" type="camera">
      <update_rate>4.0</update_rate>
      <camera name="head_r_stereo_camera">
        <horizontal_fov>1.16762527</horizontal_fov>
        <image>
          <width>1280</width>
          <height>960</height>
          <format>R8G8B8</format>
        </image>
        <clip>
          <near>0.05</near>
          <far>100</far>
        </clip>
        <noise>
          <type>gaussian</type>
          <mean>0.0</mean>
          <stddev>0.007</stddev>
        </noise>
        <distortion>
          <k1>0.0</k1>
          <k2>0.0</k2>
          <k3>0.0</k3>
          <p1>0.0</p1>
          <p2>0.0</p2>
        </distortion>
      </camera>
      <plugin filename="libgazebo_ros_camera.so" name="head_r_stereo_camera_camera_controller">
        <camera_name>head_r_stereo_camera</camera_name>
        <frame_name>head_r_stereo_camera_frame</frame_name>
        <hack_baseline>0.14</hack_baseline>
        <ros>
          <namespace></namespace>
          <remapping>head_r_stereo_camera/image_raw:=head_r_stereo_camera/image_rect_color</remapping>
        </ros>
      </plugin>
    </sensor>
  </gazebo>
  <joint name="head_center_camera_frame_joint" type="fixed">
    <origin rpy="-1.5707963267948966 0.0 -1.5707963267948966" xyz="0.0195 0.0 0.061"/>
    <parent link="head_tilt_link"/>
    <child link="head_center_camera_frame"/>
  </joint>
  <link name="head_center_camera_frame">
    <inertial>
      <origin xyz="0 0 0"/>
      <mass value="0.01"/>
      <inertia ixx="0.001" ixy="0" ixz="0" iyy="0.001" iyz="0" izz="0.001"/>
    </inertial>
  </link>
  <joint name="head_center_camera_gazebo_frame_joint" type="fixed">
    <origin rpy="1.5707963267948966 -1.5707963267948966 0.0" xyz="0 0 0"/>
    <parent link="head_center_camera_frame"/>
    <child link="head_center_camera_gazebo_frame"/>
  </joint>
  <link name="head_center_camera_gazebo_frame">
    <inertial>
      <origin xyz="0 0 0"/>
      <mass value="0.01"/>
      <inertia ixx="0.001" ixy="0" ixz="0" iyy="0.001" iyz="0" izz="0.001"/>
    </inertial>
  </link>
  <gazebo reference="head_center_camera_gazebo_frame">
    <sensor name="head_center_camera" type="camera">
      <update_rate>10.0</update_rate>
      <camera name="head_center_camera">
        <horizontal_fov>2.00</horizontal_fov>
        <image>
          <width>640</width>
          <height>480</height>
          <format>R8G8B8</format>
        </image>
        <clip>
          <near>0.01</near>
          <far>100</far>
        </clip>
        <noise>
          <type>gaussian</type>
          <mean>0.0</mean>
          <stddev>0.007</stddev>
        </noise>
        <distortion>
          <k1>0.0</k1>
          <k2>0.0</k2>
          <k3>0.0</k3>
          <p1>0.0</p1>
          <p2>0.0</p2>
        </distortion>
      </camera>
      <plugin filename="libgazebo_ros_camera.so" name="head_center_camera_camera_controller">
        <camera_name>head_center_camera</camera_name>
        <frame_name>head_center_camera_frame</frame_name>
        <hack_baseline>0.07</hack_baseline>
        <ros>
          <namespace></namespace>
        </ros>
      </plugin>
    </sensor>
  </gazebo>
  <joint name="head_rgbd_sensor_joint" type="fixed">
    <origin rpy="-1.5707963267948966 0.0 -1.5707963267948966" xyz="-0.079796 0.022 0.215172"/>
    <parent link="head_tilt_link"/>
    <child link="head_rgbd_sensor_link"/>
  </joint>
  <link name="head_rgbd_sensor_link">
    <visual>
      <origin rpy="0.0 0.0 0.0" xyz="0 0 0"/>
      <geometry>
        <mesh filename="package://hsr_description/meshes/sensors/xtion.dae"/>
      </geometry>
    </visual>
    <collision>
      <origin rpy="0.0 0.0 0.0" xyz="0 0 0"/>
      <geometry>
        <mesh filename="package://hsr_description/meshes/sensors/xtion.stl"/>
      </geometry>
    </collision>
    <inertial>
      <origin xyz="0 0 0"/>
      <mass value="0.01"/>
      <inertia ixx="0.001" ixy="0" ixz="0" iyy="0.001" iyz="0" izz="0.001"/>
    </inertial>
  </link>
  <joint name="head_rgbd_sensor_gazebo_frame_joint" type="fixed">
    <origin rpy="1.5707963267948966 -1.5707963267948966 0.0" xyz="0 0 0"/>
    <parent link="head_rgbd_sensor_link"/>
    <child link="head_rgbd_sensor_gazebo_frame"/>
  </joint>
  
        `
        
  <link name="head_rgbd_sensor_gazebo_frame">
    <inertial>
      <origin xyz="0 0 0"/>
      <mass value="0.01"/>
      <inertia ixx="0.001" ixy="0" ixz="0" iyy="0.001" iyz="0" izz="0.001"/>
    </inertial>
  </link>
  <gazebo reference="head_rgbd_sensor_gazebo_frame">
    <sensor name="openni_camera_camera" type="depth">
      <always_on>0</always_on>
      <update_rate>30</update_rate>
      <visualize>true</visualize>
      <camera>
        <horizontal_fov>1.047</horizontal_fov>
        <image>
          <width>640</width>
          <height>480</height>
          <format>B8G8R8</format>
        </image>
        <depth_camera>
                    </depth_camera>
        <clip>
          <near>0.1</near>
          <far>100</far>
        </clip>
      </camera>
      <plugin filename="libgazebo_ros_camera.so" name="head_rgbd_sensor_controller">
        <camera_name>head_rgbd_sensor</camera_name>
        <frame_name>head_rgbd_sensor_rgb_frame</frame_name>
        <hack_baseline>0</hack_baseline>
        <min_depth>0.5</min_depth>
        <max_depth>9.2</max_depth>
        <ros>
          <namespace></namespace>
          <remapping>head_rgbd_sensor/image_raw:=head_rgbd_sensor/rgb/image_rect_color</remapping>
          <remapping>head_rgbd_sensor/camera_info:=head_rgbd_sensor/rgb/camera_info</remapping>
          <remapping>head_rgbd_sensor/depth/image_raw:=head_rgbd_sensor/depth_registered/image_rect_raw</remapping>
          <remapping>head_rgbd_sensor/depth/camera_info:=head_rgbd_sensor/depth_registered/camera_info</remapping>
          <remapping>head_rgbd_sensor/points:=head_rgbd_sensor/depth_registered/rectified_points</remapping>
        </ros>
      </plugin>
    </sensor>
  </gazebo>
  <gazebo reference="head_pan_link">
    <selfCollide>False</selfCollide>
    <gravity>True</gravity>
    <mu1>0.9</mu1>
    <mu2>0.9</mu2>
  </gazebo>
  <gazebo reference="head_tilt_link">
    <selfCollide>False</selfCollide>
    <gravity>True</gravity>
    <mu1>0.9</mu1>
    <mu2>0.9</mu2>
  </gazebo>
  <gazebo reference="head_l_stereo_camera_link">
    <selfCollide>False</selfCollide>
    <gravity>True</gravity>
    <mu1>0.9</mu1>
    <mu2>0.9</mu2>
  </gazebo>
  <gazebo reference="head_r_stereo_camera_link">
    <selfCollide>False</selfCollide>
    <gravity>True</gravity>
    <mu1>0.9</mu1>
    <mu2>0.9</mu2>
  </gazebo>
  <gazebo reference="head_center_camera_frame">
    <selfCollide>False</selfCollide>
    <gravity>False</gravity>
    <mu1>0.9</mu1>
    <mu2>0.9</mu2>
  </gazebo>
  <gazebo reference="head_rgbd_sensor_link">
    <selfCollide>False</selfCollide>
    <gravity>True</gravity>
    <mu1>0.9</mu1>
    <mu2>0.9</mu2>
  </gazebo>
  <gazebo reference="head_pan_joint">
  </gazebo>
  <gazebo reference="head_tilt_joint">
  </gazebo>
  <joint name="arm_lift_joint" type="prismatic">
    <origin rpy="0.0 0.0 0.0" xyz="0.0 0.0 0.340"/>
    <axis xyz="0.0 0.0 1.0"/>
    <limit effort="300.0" lower="0.005" upper="0.67" velocity="0.15"/>
    <safety_controller k_position="100" k_velocity="200000" soft_lower_limit="0.005" soft_upper_limit="0.67"/>
    <parent link="base_link"/>
    <child link="arm_lift_link"/>
    <dynamics damping="1.0"/>
  </joint>
  <link name="arm_lift_link">
    <inertial>
      <mass value="1.275819"/>
      <origin xyz="0.051549 0.042438 -0.064145"/>
      <inertia ixx="0.004633" ixy="0.000475272668" ixz="-0.002403" iyy="0.008065" iyz="-0.000100268629" izz="0.007672"/>
    </inertial>
    <visual>
      <geometry>
        <mesh filename="package://hsr_description/meshes/arm_v0/shoulder.dae"/>
      </geometry>
    </visual>
    <collision>
      <geometry>
        <mesh filename="package://hsr_description/meshes/arm_v0/shoulder.stl"/>
      </geometry>
    </collision>
  </link>
  <joint name="arm_flex_joint" type="revolute">
    <origin rpy="0.0 0.0 0.0" xyz="0.141 0.078 0.0"/>
    <axis xyz="0.0 -1.0 0.0"/>
    <!--limit effort="100.0" velocity="1.2" lower="-2.62" upper="0.0" /-->
    <limit effort="100.0" lower="-2.61" upper="-0.03" velocity="1.2"/>
    <safety_controller k_position="100" k_velocity="200000" soft_lower_limit="-2.61" soft_upper_limit="-0.03"/>
    <parent link="arm_lift_link"/>
    <child link="arm_flex_link"/>
    <dynamics damping="1.0"/>
  </joint>
  <link name="arm_flex_link">
    <!--             <inertial>
                <mass value="1.339295"/>
                <origin xyz="0.000632 0.006404 0.118529"/>
                <inertia ixx="7.528" ixy="-0.000020284207" ixz="-0.000022947194"
                    iyy="0.007102" iyz="-0.000091796075" izz="0.001552"/>
            </inertial> -->
    <visual>
      <geometry>
        <mesh filename="package://hsr_description/meshes/arm_v0/arm_flex_light.dae"/>
      </geometry>
    </visual>
    <collision>
      <geometry>
        <mesh filename="package://hsr_description/meshes/arm_v0/arm_flex.stl"/>
      </geometry>
    </collision>
  </link>
  <joint name="arm_roll_joint" type="revolute">
    <origin rpy="0.0 0.0 0.0" xyz="0.005 0.0 0.345"/>
    <axis xyz="0.0 0.0 1.0"/>
    <limit effort="100.0" lower="-1.95" upper="3.67" velocity="2.0"/>
    <safety_controller k_position="100" k_velocity="200000" soft_lower_limit="-1.95" soft_upper_limit="3.67"/>
    <parent link="arm_flex_link"/>
    <child link="arm_roll_link"/>
    <dynamics damping="0.1"/>
  </joint>
  <link name="arm_roll_link">
    <inertial>
      <mass value="0.247936"/>
      <origin xyz="-0.006927 0.002039 -0.064837"/>
      <inertia ixx="0.004267" ixy="-0.000018322199" ixz="0.000017984455" iyy="0.000780923828" iyz="-0.00001392334" izz="0.00412"/>
    </inertial>
    <visual>
      <geometry>
        <mesh filename="package://hsr_description/meshes/arm_v0/arm_roll_light.dae"/>
      </geometry>
    </visual>
    <collision>
      <geometry>
        <mesh filename="package://hsr_description/meshes/arm_v0/arm_roll.stl"/>
      </geometry>
    </collision>
  </link>
  <gazebo reference="arm_lift_link">
    <selfCollide>False</selfCollide>
    <gravity>True</gravity>
    <mu1>0.9</mu1>
    <mu2>0.9</mu2>
  </gazebo>
  <gazebo reference="arm_flex_link">
    <selfCollide>False</selfCollide>
    <gravity>True</gravity>
    <mu1>0.9</mu1>
    <mu2>0.9</mu2>
  </gazebo>
  <gazebo reference="arm_roll_link">
    <selfCollide>False</selfCollide>
    <gravity>True</gravity>
    <mu1>0.9</mu1>
    <mu2>0.9</mu2>
  </gazebo>
  <gazebo reference="arm_lift_joint">
  </gazebo>
  <gazebo reference="arm_flex_joint">
  </gazebo>
  <gazebo reference="arm_roll_joint">
  </gazebo>
  <joint name="wrist_flex_joint" type="revolute">
    <origin rpy="0.0 0.0 0.0" xyz="0.0 0.0 0.0"/>
    <axis xyz="0.0 -1.0 0.0"/>
    <!--limit effort="100.0" velocity="1.5" lower="-1.92" upper="1.22" /-->
    <limit effort="100.0" lower="-1.91" upper="1.21" velocity="1.5"/>
    <safety_controller k_position="100" k_velocity="200000" soft_lower_limit="-1.91" soft_upper_limit="1.21"/>
    <parent link="arm_roll_link"/>
    <child link="wrist_flex_link"/>
    <dynamics damping="1.0"/>
  </joint>
  <link name="wrist_flex_link">
    <inertial>
      <mass value="0.681225"/>
      <origin xyz="0.000131 -0.003929 0.00217"/>
      <inertia ixx="0.000074353558" ixy="0.000000494515" ixz="0.000000022937" iyy="0.000038432887" iyz="-0.00000255576" izz="0.000064680918"/>
    </inertial>
    <visual>
      <geometry>
        <mesh filename="package://hsr_description/meshes/wrist_v0/wrist_flex.dae"/>
      </geometry>
      <material name="body_sub"/>
    </visual>
    <visual>
      <origin rpy="0.0 0.0 0.0" xyz="0.0 0.0 0.04"/>
      <geometry>
        <cylinder length="0.02" radius="0.017"/>
      </geometry>
      <material name="body_sub"/>
    </visual>
    <collision>
      <origin rpy="0.0 0.0 0.0" xyz="0.0 0.0 0.03"/>
      <geometry>
        <cylinder length="0.04" radius="0.017"/>
      </geometry>
    </collision>
  </link>
  <joint name="wrist_roll_joint" type="revolute">
    <origin rpy="0.0 0.0 0.0" xyz="0.0 0.0 0.0"/>
    <axis xyz="0.0 0.0 1.0"/>
    <!--limit effort="100.0" velocity="1.5" lower="-1.92" upper="3.67" /-->
    <limit effort="100.0" lower="-1.91" upper="3.63" velocity="1.5"/>
    <safety_controller k_position="100" k_velocity="200000" soft_lower_limit="-1.91" soft_upper_limit="3.63"/>
    <parent link="wrist_flex_link"/>
    <child link="wrist_ft_sensor_mount_link"/>
    <dynamics damping="1.0"/>
  </joint>
  <!-- each link must have mass in URDF so we apply very small mass (10 gram) for this coupling link -->
  <link name="wrist_ft_sensor_mount_link">
    <inertial>
      <mass value="0.01"/>
      <inertia ixx="0.001" ixy="0.0" ixz="0.0" iyy="0.001" iyz="0.0" izz="0.001"/>
    </inertial>
  </link>
  <joint name="wrist_ft_sensor_frame_inverse_joint" type="fixed">
    <origin rpy="-3.141592653589793 0.0 0.0" xyz="0.0 0.0 0.0735"/>
    <parent link="wrist_ft_sensor_frame"/>
    <child link="wrist_roll_link"/>
  </joint>
  <link name="wrist_roll_link">
    <inertial>
      <mass value="0.761692"/>
      <origin xyz="-0.001416 -0.001547 0.081689"/>
      <inertia ixx="0.000805633819" ixy="-0.000014431758" ixz="0.000028204659" iyy="0.000768077165" iyz="0.000022460226" izz="0.000453406611"/>
    </inertial>
    <visual>
      <geometry>
        <mesh filename="package://hsr_description/meshes/wrist_v0/wrist_roll.dae"/>
      </geometry>
    </visual>
    <collision>
      <geometry>
        <mesh filename="package://hsr_description/meshes/wrist_v0/wrist_roll.stl"/>
      </geometry>
    </collision>
  </link>
  <joint name="wrist_ft_sensor_frame_joint" type="fixed">
    <origin rpy="3.141592653589793 0.0 0.0" xyz="0.0 0.0 0.0735"/>
    <parent link="wrist_ft_sensor_mount_link"/>
    <child link="wrist_ft_sensor_frame"/>
  </joint>
  <link name="wrist_ft_sensor_frame">
    <inertial>
      <origin xyz="0 0 0"/>
      <mass value="0.01"/>
      <inertia ixx="0.001" ixy="0" ixz="0" iyy="0.001" iyz="0" izz="0.001"/>
    </inertial>
  </link>
  <gazebo reference="wrist_ft_sensor_frame_joint">
    <provideFeedback>true</provideFeedback>
  </gazebo>
  <gazebo>
    <plugin filename="libgazebo_ros_ft_sensor.so" name="ft_sensor">
      <update_rate>30.0</update_rate>
      <joint_name>wrist_ft_sensor_frame_joint</joint_name>
      <robotNamespace></robotNamespace>
      <ros>
        <namespace></namespace>
        <remapping>wrench:=wrist_wrench/raw</remapping>
      </ros>
    </plugin>
  </gazebo>
  <gazebo reference="wrist_flex_link">
    <selfCollide>False</selfCollide>
    <gravity>True</gravity>
    <mu1>0.9</mu1>
    <mu2>0.9</mu2>
  </gazebo>
  <gazebo reference="wrist_roll_link">
    <selfCollide>False</selfCollide>
    <gravity>True</gravity>
    <mu1>0.9</mu1>
    <mu2>0.9</mu2>
  </gazebo>
  <gazebo reference="wrist_ft_sensor_frame">
    <selfCollide>False</selfCollide>
    <gravity>True</gravity>
    <mu1>0.9</mu1>
    <mu2>0.9</mu2>
  </gazebo>
  <gazebo reference="wrist_flex_joint">
  </gazebo>
  <gazebo reference="wrist_roll_joint">
  </gazebo>
  <joint name="hand_palm_joint" type="fixed">
    <origin rpy="0.0 0.0 3.141592653589793" xyz="0.012 0.0 0.1405"/>
    <parent link="wrist_roll_link"/>
    <child link="hand_palm_link"/>
  </joint>
  <link name="hand_palm_link">
    <inertial>
      <mass value="0.15"/>
      <inertia ixx="0.015" ixy="0.0" ixz="0.0" iyy="0.015" iyz="0.0" izz="0.015"/>
    </inertial>
    <visual>
      <geometry>
        <mesh filename="package://hsr_description/meshes/hand_v0/palm_light.dae"/>
      </geometry>
      <material name="body_sub"/>
    </visual>
    <collision>
      <geometry>
        <mesh filename="package://hsr_description/meshes/hand_v0/palm.stl"/>
      </geometry>
    </collision>
  </link>
  <joint name="hand_motor_joint" type="revolute">
    <axis xyz="1.0 0.0 0.0"/>
    <limit effort="100.0" lower="-0.798" upper="1.24" velocity="1.0"/>
    <parent link="hand_palm_link"/>
    <child link="hand_motor_dummy_link"/>
    <dynamics damping="0.0001"/>
  </joint>
  <link name="hand_motor_dummy_link">
    <inertial>
      <mass value="0.15"/>
      <inertia ixx="0.015" ixy="0.0" ixz="0.0" iyy="0.015" iyz="0.0" izz="0.015"/>
    </inertial>
  </link>
  <joint name="hand_l_proximal_joint" type="revolute">
    <origin rpy="0.0 0.0 0.0" xyz="-0.01675 -0.0245 -0.0175"/>
    <axis xyz="1.0 0.0 0.0"/>
    <limit effort="100.0" lower="-0.798" upper="1.24" velocity="1.0"/>
    <parent link="hand_palm_link"/>
    <child link="hand_l_proximal_link"/>
    <mimic joint="hand_motor_joint"/>
    <dynamics damping="0.0001"/>
  </joint>
  <link name="hand_l_proximal_link">
    <inertial>
      <mass value="0.15"/>
      <inertia ixx="0.015" ixy="0.0" ixz="0.0" iyy="0.015" iyz="0.0" izz="0.015"/>
    </inertial>
  </link>
  <joint name="hand_l_spring_proximal_joint" type="revolute">
    <axis xyz="1.0 0.0 0.0"/>
    <limit effort="10.0" lower="0.0" upper="0.698" velocity="1.0"/>
    <parent link="hand_l_proximal_link"/>
    <child link="hand_l_spring_proximal_link"/>
    <dynamics damping="0.0001"/>
  </joint>
  <link name="hand_l_spring_proximal_link">
    <inertial>
      <mass value="0.043589"/>
      <origin xyz="0.021418 0.00248 0.022688"/>
      <inertia ixx="0.000026033886" ixy="-0.000000144078" ixz="-0.00000198241" iyy="0.000028824811" iyz="-0.000001268421" izz="0.000005135919"/>
    </inertial>
    <visual>
      <geometry>
        <mesh filename="package://hsr_description/meshes/hand_v0/l_proximal.dae"/>
      </geometry>
      <material name="body_sub"/>
    </visual>
    <collision>
      <geometry>
        <mesh filename="package://hsr_description/meshes/hand_v0/l_proximal.stl"/>
      </geometry>
    </collision>
  </link>
  <joint name="hand_l_mimic_distal_joint" type="revolute">
    <origin xyz="0.0 0.0 0.07"/>
    <axis xyz="1.0 0.0 0.0"/>
    <limit effort="100.0" lower="-0.698" upper="-0.0" velocity="1.0"/>
    <parent link="hand_l_spring_proximal_link"/>
    <child link="hand_l_mimic_distal_link"/>
    <mimic joint="hand_l_spring_proximal_joint" multiplier="-1.0"/>
    <dynamics damping="0.0001"/>
  </joint>
  <link name="hand_l_mimic_distal_link">
    <inertial>
      <mass value="0.15"/>
      <inertia ixx="0.015" ixy="0.0" ixz="0.0" iyy="0.015" iyz="0.0" izz="0.015"/>
    </inertial>
  </link>
  <joint name="hand_l_distal_joint" type="revolute">
    <axis xyz="1.0 0.0 0.0"/>
    <limit effort="100.0" lower="-1.24" upper="0.798" velocity="1.0"/>
    <parent link="hand_l_mimic_distal_link"/>
    <child link="hand_l_distal_link"/>
    <mimic joint="hand_motor_joint" multiplier="-1.0" offset="-0.087"/>
    <dynamics damping="0.0001"/>
  </joint>
  <link name="hand_l_distal_link">
    <!--             <inertial>
                <mass value="0.027731"/>
                <origin xyz="0.011116 0.005679 0.017532"/>
                <inertia
                    ixx="0.000004451952" ixy="-0.000000617574" ixz="0.000000503765"
                    iyy="0.000000503765" iyz="-0.000000435048" izz="0.000004456764"/>
            </inertial> -->
    <visual>
      <geometry>
        <mesh filename="package://hsr_description/meshes/hand_v0/l_distal.dae"/>
      </geometry>
    </visual>
    <collision>
      <geometry>
        <mesh filename="package://hsr_description/meshes/hand_v0/l_distal.stl"/>
      </geometry>
    </collision>
  </link>
  <joint name="hand_l_finger_tip_frame_joint" type="fixed">
    <origin rpy="-1.5707963267948966 0.0 0.0" xyz="0.01675 0.0193 0.0379"/>
    <parent link="hand_l_distal_link"/>
    <child link="hand_l_finger_tip_frame"/>
    <dynamics damping="0.0001"/>
  </joint>
  <link name="hand_l_finger_tip_frame">
    <inertial>
      <mass value="0.15"/>
      <inertia ixx="0.015" ixy="0.0" ixz="0.0" iyy="0.015" iyz="0.0" izz="0.015"/>
    </inertial>
  </link>
  <joint name="hand_l_finger_vacuum_frame_joint" type="fixed">
    <origin rpy="0.7853981633974483 0.0 0.0" xyz="0.00475 -0.011539 0.03322"/>
    <parent link="hand_l_distal_link"/>
    <child link="hand_l_finger_vacuum_frame"/>
  </joint>
  <link name="hand_l_finger_vacuum_frame">
    <inertial>
      <mass value="0.15"/>
      <inertia ixx="0.015" ixy="0.0" ixz="0.0" iyy="0.015" iyz="0.0" izz="0.015"/>
    </inertial>
    <visual>
      <origin rpy="0.0 0.0 0.0" xyz="0.0 0.0 -0.01"/>
      <geometry>
        <box size="0.008 0.008 0.02"/>
      </geometry>
      <material name="body_sub"/>
    </visual>
  </link>
  <joint name="hand_r_proximal_joint" type="revolute">
    <origin rpy="0.0 0.0 0.0" xyz="-0.01675 0.0245 -0.0175"/>
    <axis xyz="-1.0 0.0 0.0"/>
    <limit effort="100.0" lower="-0.798" upper="1.24" velocity="1.0"/>
    <parent link="hand_palm_link"/>
    <child link="hand_r_proximal_link"/>
    <mimic joint="hand_motor_joint"/>
    <dynamics damping="0.0001"/>
  </joint>
  <link name="hand_r_proximal_link">
    <inertial>
      <mass value="0.15"/>
      <inertia ixx="0.015" ixy="0.0" ixz="0.0" iyy="0.015" iyz="0.0" izz="0.015"/>
    </inertial>
  </link>
  <joint name="hand_r_spring_proximal_joint" type="revolute">
    <axis xyz="-1.0 0.0 0.0"/>
    <limit effort="10.0" lower="0.0" upper="0.698" velocity="1.0"/>
    <parent link="hand_r_proximal_link"/>
    <child link="hand_r_spring_proximal_link"/>
    <dynamics damping="0.0001"/>
  </joint>
  <link name="hand_r_spring_proximal_link">
    <inertial>
      <mass value="0.043956"/>
      <origin xyz="0.013203 0.002096 0.023311"/>
      <inertia ixx="0.00002623664" ixy="0.00000001631" ixz="0.000001281845" iyy="0.000028838232" iyz="-0.000001621709" izz="0.000004957151"/>
    </inertial>
    <visual>
      <geometry>
        <mesh filename="package://hsr_description/meshes/hand_v0/r_proximal.dae"/>
      </geometry>
    </visual>
    <collision>
      <geometry>
        <mesh filename="package://hsr_description/meshes/hand_v0/r_proximal.stl"/>
      </geometry>
    </collision>
  </link>
  <joint name="hand_r_mimic_distal_joint" type="revolute">
    <origin xyz="0.0 0.0 0.07"/>
    <axis xyz="-1.0 0.0 0.0"/>
    <limit effort="100.0" lower="-0.698" upper="-0.0" velocity="1.0"/>
    <parent link="hand_r_spring_proximal_link"/>
    <child link="hand_r_mimic_distal_link"/>
    <mimic joint="hand_r_spring_proximal_joint" multiplier="-1.0"/>
    <dynamics damping="0.0001"/>
  </joint>
  <link name="hand_r_mimic_distal_link">
    <inertial>
      <mass value="0.15"/>
      <inertia ixx="0.015" ixy="0.0" ixz="0.0" iyy="0.015" iyz="0.0" izz="0.015"/>
    </inertial>
  </link>
  <joint name="hand_r_distal_joint" type="revolute">
    <axis xyz="-1.0 0.0 0.0"/>
    <limit effort="100.0" lower="-1.24" upper="0.798" velocity="1.0"/>
    <parent link="hand_r_mimic_distal_link"/>
    <child link="hand_r_distal_link"/>
    <mimic joint="hand_motor_joint" multiplier="-1.0" offset="-0.087"/>
    <dynamics damping="0.0001"/>
  </joint>
  <link name="hand_r_distal_link">
    <inertial>
      <mass value="0.020927"/>
      <origin xyz="0.014256 -0.008321 0.015591"/>
      <inertia ixx="0.00000307518" ixy="-0.00000004954" ixz="0.000000009481" iyy="0.000004074079" iyz="0.000000843648" izz="0.000002807795"/>
    </inertial>
    <visual>
      <geometry>
        <mesh filename="package://hsr_description/meshes/hand_v0/r_distal.dae"/>
      </geometry>
    </visual>
    <collision>
      <geometry>
        <mesh filename="package://hsr_description/meshes/hand_v0/r_distal.stl"/>
      </geometry>
    </collision>
  </link>
  <joint name="hand_r_finger_tip_frame_joint" type="fixed">
    <origin rpy="1.5707963267948966 0.0 0.0" xyz="0.01675 -0.0193 0.0379"/>
    <parent link="hand_r_distal_link"/>
    <child link="hand_r_finger_tip_frame"/>
  </joint>
  <link name="hand_r_finger_tip_frame">
    <inertial>
      <mass value="0.15"/>
      <inertia ixx="0.015" ixy="0.0" ixz="0.0" iyy="0.015" iyz="0.0" izz="0.015"/>
    </inertial>
  </link>
  <joint name="hand_camera_frame_joint" type="fixed">
    <origin rpy="0.0 0.0 0.0" xyz="0.039 0.0 -0.0045"/>
    <parent link="hand_palm_link"/>
    <child link="hand_camera_frame"/>
  </joint>
  <link name="hand_camera_frame">
    <inertial>
      <origin xyz="0 0 0"/>
      <mass value="0.01"/>
      <inertia ixx="0.001" ixy="0" ixz="0" iyy="0.001" iyz="0" izz="0.001"/>
    </inertial>
  </link>
  <joint name="hand_camera_gazebo_frame_joint" type="fixed">
    <origin rpy="1.5707963267948966 -1.5707963267948966 0" xyz="0 0 0"/>
    <parent link="hand_camera_frame"/>
    <child link="hand_camera_gazebo_frame"/>
  </joint>
  <link name="hand_camera_gazebo_frame">
    <inertial>
      <origin xyz="0 0 0"/>
      <mass value="0.01"/>
      <inertia ixx="0.001" ixy="0" ixz="0" iyy="0.001" iyz="0" izz="0.001"/>
    </inertial>
  </link>
  <gazebo reference="hand_camera_gazebo_frame">
    <sensor name="hand_camera" type="camera">
      <update_rate>10.0</update_rate>
      <camera name="hand_camera">
        <horizontal_fov>2.00</horizontal_fov>
        <image>
          <width>640</width>
          <height>480</height>
          <format>R8G8B8</format>
        </image>
        <clip>
          <near>0.01</near>
          <far>100</far>
        </clip>
        <noise>
          <type>gaussian</type>
          <mean>0.0</mean>
          <stddev>0.007</stddev>
        </noise>
        <distortion>
          <k1>0.0</k1>
          <k2>0.0</k2>
          <k3>0.0</k3>
          <p1>0.0</p1>
          <p2>0.0</p2>
        </distortion>
      </camera>
      <plugin filename="libgazebo_ros_camera.so" name="hand_camera_camera_controller">
        <camera_name>hand_camera</camera_name>
        <frame_name>hand_camera_frame</frame_name>
        <hack_baseline>0.07</hack_baseline>
        <ros>
          <namespace></namespace>
        </ros>
      </plugin>
    </sensor>
  </gazebo>
  <gazebo reference="hand_palm_link">
    <selfCollide>False</selfCollide>
    <gravity>True</gravity>
    <mu1>0.9</mu1>
    <mu2>0.9</mu2>
  </gazebo>
  <gazebo reference="hand_camera_frame">
    <selfCollide>False</selfCollide>
    <gravity>False</gravity>
    <mu1>0.9</mu1>
    <mu2>0.9</mu2>
  </gazebo>
  <gazebo reference="hand_l_proximal_link">
    <selfCollide>False</selfCollide>
    <gravity>True</gravity>
    <mu1>1.0</mu1>
    <mu2>1.0</mu2>
  </gazebo>
  <gazebo reference="hand_l_spring_proximal_link">
    <selfCollide>False</selfCollide>
    <gravity>True</gravity>
    <mu1>1.0</mu1>
    <mu2>1.0</mu2>
  </gazebo>
  <gazebo reference="hand_l_mimic_distal_link">
    <selfCollide>False</selfCollide>
    <gravity>True</gravity>
    <mu1>1.0</mu1>
    <mu2>1.0</mu2>
  </gazebo>
  <gazebo reference="hand_l_distal_link">
    <selfCollide>False</selfCollide>
    <gravity>True</gravity>
    <mu1>1.0</mu1>
    <mu2>1.0</mu2>
  </gazebo>
  <gazebo reference="hand_l_finger_tip_frame">
    <selfCollide>False</selfCollide>
    <gravity>False</gravity>
    <mu1>1.0</mu1>
    <mu2>1.0</mu2>
  </gazebo>
  <gazebo reference="hand_l_finger_vacuum_frame">
    <selfCollide>False</selfCollide>
    <gravity>False</gravity>
    <mu1>1.0</mu1>
    <mu2>1.0</mu2>
  </gazebo>
  <gazebo reference="hand_r_proximal_link">
    <selfCollide>False</selfCollide>
    <gravity>True</gravity>
    <mu1>1.0</mu1>
    <mu2>1.0</mu2>
  </gazebo>
  <gazebo reference="hand_r_spring_proximal_link">
    <selfCollide>False</selfCollide>
    <gravity>True</gravity>
    <mu1>1.0</mu1>
    <mu2>1.0</mu2>
  </gazebo>
  <gazebo reference="hand_r_mimic_distal_link">
    <selfCollide>False</selfCollide>
    <gravity>True</gravity>
    <mu1>1.0</mu1>
    <mu2>1.0</mu2>
  </gazebo>
  <gazebo reference="hand_r_distal_link">
    <selfCollide>False</selfCollide>
    <gravity>False</gravity>
    <mu1>1.0</mu1>
    <mu2>1.0</mu2>
  </gazebo>
  <gazebo reference="hand_r_finger_tip_frame">
    <selfCollide>False</selfCollide>
    <gravity>False</gravity>
    <mu1>1.0</mu1>
    <mu2>1.0</mu2>
  </gazebo>
  <gazebo reference="hand_palm_joint">
  </gazebo>
  <gazebo reference="hand_motor_joint">
  </gazebo>
  <gazebo reference="hand_l_proximal_joint">
  </gazebo>
  <gazebo reference="hand_l_spring_proximal_joint">
  </gazebo>
  <gazebo reference="hand_l_mimic_distal_joint">
  </gazebo>
  <gazebo reference="hand_l_distal_joint">
  </gazebo>
  <gazebo reference="hand_r_proximal_joint">
  </gazebo>
  <gazebo reference="hand_r_spring_proximal_joint">
  </gazebo>
  <gazebo reference="hand_r_mimic_distal_joint">
  </gazebo>
  <gazebo reference="hand_r_distal_joint">
  </gazebo>
  <joint name="hand_gripper_tool_frame_joint" type="fixed">
    <origin rpy="0.0 0.0 0.0" xyz="0.0 0.0 0.07"/>
    <parent link="hand_palm_link"/>
    <child link="hand_gripper_tool_frame"/>
  </joint>
  <link name="hand_gripper_tool_frame"/>
  <ros2_control name="hsrb" type="system">
    <hardware>
      <plugin>hsrb_robot_hardware/HsrbHW</plugin>
    </hardware>
    <joint name="arm_lift_joint">
      <command_interface name="position">
        <param name="min">0.0</param>
        <param name="max">0.69</param>
      </command_interface>
      <command_interface name="velocity">
        <param name="min">-6.05</param>
        <param name="max">6.05</param>
      </command_interface>
      <state_interface name="position"/>
      <state_interface name="velocity"/>
      <state_interface name="effort"/>
      <param name="control_type">ActiveJoint</param>
      <param name="motor_id">21</param>
      <param name="reduction">40.273862263</param>
      <param name="drive_mode">5</param>
      <param name="velocity_limit">6.05</param>
      <param name="acceleration_limit">1000.0</param>
      <param name="gear_ratio">0.002407705</param>
      <param name="torque_constant">0.0174</param>
    </joint>
    <joint name="arm_flex_joint">
      <command_interface name="position">
        <param name="min">-2.62</param>
        <param name="max">0.0</param>
      </command_interface>
      <command_interface name="velocity">
        <param name="min">-1.0</param>
        <param name="max">1.0</param>
      </command_interface>
      <state_interface name="position"/>
      <state_interface name="velocity"/>
      <state_interface name="effort"/>
      <param name="control_type">ActiveJoint</param>
      <param name="motor_id">22</param>
      <param name="reduction">1.0</param>
      <param name="drive_mode">5</param>
      <param name="velocity_limit">1.0</param>
      <param name="acceleration_limit">1000.0</param>
      <param name="gear_ratio">0.00128576</param>
      <param name="torque_constant">0.0208</param>
    </joint>
    <joint name="arm_roll_joint">
      <command_interface name="position">
        <param name="min">-2.09</param>
        <param name="max">3.84</param>
      </command_interface>
      <command_interface name="velocity">
        <param name="min">-1.0</param>
        <param name="max">1.0</param>
      </command_interface>
      <state_interface name="position"/>
      <state_interface name="velocity"/>
      <state_interface name="effort"/>
      <param name="control_type">ActiveJoint</param>
      <param name="motor_id">23</param>
      <param name="reduction">1.0</param>
      <param name="drive_mode">5</param>
      <param name="velocity_limit">1.0</param>
      <param name="acceleration_limit">1000.0</param>
      <param name="gear_ratio">0.003333333</param>
      <param name="torque_constant">0.0184</param>
    </joint>
    <joint name="wrist_flex_joint">
      <command_interface name="position">
        <param name="min">-1.92</param>
        <param name="max">1.22</param>
      </command_interface>
      <command_interface name="velocity">
        <param name="min">-1.0</param>
        <param name="max">1.0</param>
      </command_interface>
      <state_interface name="position"/>
      <state_interface name="velocity"/>
      <state_interface name="effort"/>
      <param name="control_type">ActiveJoint</param>
      <param name="motor_id">24</param>
      <param name="reduction">1.0</param>
      <param name="drive_mode">5</param>
      <param name="velocity_limit">1.0</param>
      <param name="acceleration_limit">1000.0</param>
      <param name="gear_ratio">0.0035</param>
      <param name="torque_constant">0.0184</param>
    </joint>
    <joint name="wrist_roll_joint">
      <command_interface name="position">
        <param name="min">-1.92</param>
        <param name="max">3.67</param>
      </command_interface>
      <command_interface name="velocity">
        <param name="min">-1.0</param>
        <param name="max">1.0</param>
      </command_interface>
      <state_interface name="position"/>
      <state_interface name="velocity"/>
      <state_interface name="effort"/>
      <param name="control_type">ActiveJoint</param>
      <param name="motor_id">25</param>
      <param name="reduction">1.0</param>
      <param name="drive_mode">7</param>
      <param name="velocity_limit">1.0</param>
      <param name="acceleration_limit">1000.0</param>
      <param name="gear_ratio">0.0035</param>
      <param name="torque_constant">0.0184</param>
    </joint>
    <joint name="head_pan_joint">
      <command_interface name="position">
        <param name="min">-3.84</param>
        <param name="max">1.75</param>
      </command_interface>
      <command_interface name="velocity">
        <param name="min">-1.0</param>
        <param name="max">1.0</param>
      </command_interface>
      <state_interface name="position"/>
      <state_interface name="velocity"/>
      <state_interface name="effort"/>
      <param name="control_type">ActiveJoint</param>
      <param name="motor_id">31</param>
      <param name="reduction">1.0</param>
      <param name="drive_mode">5</param>
      <param name="velocity_limit">1.0</param>
      <param name="acceleration_limit">1000.0</param>
      <param name="gear_ratio">0.01</param>
      <param name="torque_constant">0.0184</param>
    </joint>
    <joint name="head_tilt_joint">
      <command_interface name="position">
        <param name="min">-1.57</param>
        <param name="max">0.52</param>
      </command_interface>
      <command_interface name="velocity">
        <param name="min">-1.0</param>
        <param name="max">1.0</param>
      </command_interface>
      <state_interface name="position"/>
      <state_interface name="velocity"/>
      <state_interface name="effort"/>
      <param name="control_type">ActiveJoint</param>
      <param name="motor_id">32</param>
      <param name="reduction">-1.0</param>
      <param name="drive_mode">5</param>
      <param name="velocity_limit">1.0</param>
      <param name="acceleration_limit">1000.0</param>
      <param name="gear_ratio">0.0028</param>
      <param name="torque_constant">0.0184</param>
    </joint>
    <joint name="hand_motor_joint">
      <command_interface name="position">
        <param name="min">-0.798</param>
        <param name="max">1.24</param>
      </command_interface>
      <state_interface name="position"/>
      <state_interface name="velocity"/>
      <state_interface name="effort"/>
      <param name="control_type">Gripper</param>
      <param name="motor_id">41</param>
      <param name="reduction">1.0</param>
      <param name="drive_mode">0</param>
      <param name="velocity_limit">3.0</param>
      <param name="acceleration_limit">1000.0</param>
      <param name="gear_ratio">0.005090909</param>
      <param name="torque_constant">0.0184</param>
      <param name="left_spring_joint">hand_l_spring_proximal_joint</param>
      <param name="right_spring_joint">hand_r_spring_proximal_joint</param>
    </joint>
    <joint name="base_l_drive_wheel_joint">
      <command_interface name="position">
        <param name="min">-999999</param>
        <param name="max">999999</param>
      </command_interface>
      <command_interface name="velocity">
        <param name="min">-20.8</param>
        <param name="max">20.8</param>
      </command_interface>
      <state_interface name="position"/>
      <state_interface name="velocity"/>
      <state_interface name="effort"/>
      <param name="control_type">Wheel</param>
      <param name="motor_id">11</param>
      <param name="reduction">1.0</param>
      <param name="drive_mode">3</param>
      <param name="velocity_limit">20.8</param>
      <param name="acceleration_limit">41.7</param>
      <param name="gear_ratio">0.006451613</param>
      <param name="torque_constant">0.0174</param>
    </joint>
    <joint name="base_r_drive_wheel_joint">
      <command_interface name="position">
        <param name="min">-999999</param>
        <param name="max">999999</param>
      </command_interface>
      <command_interface name="velocity">
        <param name="min">-20.8</param>
        <param name="max">20.8</param>
      </command_interface>
      <state_interface name="position"/>
      <state_interface name="velocity"/>
      <state_interface name="effort"/>
      <param name="control_type">Wheel</param>
      <param name="motor_id">12</param>
      <param name="reduction">1.0</param>
      <param name="drive_mode">3</param>
      <param name="velocity_limit">20.8</param>
      <param name="acceleration_limit">41.7</param>
      <param name="gear_ratio">0.006451613</param>
      <param name="torque_constant">0.0174</param>
    </joint>
    <joint name="base_roll_joint">
      <command_interface name="position">
        <param name="min">-999999</param>
        <param name="max">999999</param>
      </command_interface>
      <command_interface name="velocity">
        <param name="min">-2.5</param>
        <param name="max">2.5</param>
      </command_interface>
      <state_interface name="position"/>
      <state_interface name="velocity"/>
      <state_interface name="effort"/>
      <param name="control_type">ActiveJoint</param>
      <param name="motor_id">13</param>
      <param name="reduction">-1.0</param>
      <param name="drive_mode">3</param>
      <param name="velocity_limit">2.5</param>
      <param name="acceleration_limit">5.0</param>
      <param name="gear_ratio">0.003333333</param>
      <param name="torque_constant">0.0368</param>
    </joint>
  </ros2_control>
</robot>
